2020-04-22 22:13:17,435 ERROR: Exception on /translate [POST] [in c:\users\shikhar singh\appdata\local\programs\python\python37\lib\site-packages\flask\app.py:1891]
Traceback (most recent call last):
  File "c:\users\shikhar singh\appdata\local\programs\python\python37\lib\site-packages\urllib3\connection.py", line 157, in _new_conn
    (self._dns_host, self.port), self.timeout, **extra_kw
  File "c:\users\shikhar singh\appdata\local\programs\python\python37\lib\site-packages\urllib3\util\connection.py", line 61, in create_connection
    for res in socket.getaddrinfo(host, port, family, socket.SOCK_STREAM):
  File "c:\users\shikhar singh\appdata\local\programs\python\python37\lib\socket.py", line 748, in getaddrinfo
    for res in _socket.getaddrinfo(host, port, family, type, proto, flags):
socket.gaierror: [Errno 11001] getaddrinfo failed

During handling of the above exception, another exception occurred:

Traceback (most recent call last):
  File "c:\users\shikhar singh\appdata\local\programs\python\python37\lib\site-packages\urllib3\connectionpool.py", line 672, in urlopen
    chunked=chunked,
  File "c:\users\shikhar singh\appdata\local\programs\python\python37\lib\site-packages\urllib3\connectionpool.py", line 376, in _make_request
    self._validate_conn(conn)
  File "c:\users\shikhar singh\appdata\local\programs\python\python37\lib\site-packages\urllib3\connectionpool.py", line 994, in _validate_conn
    conn.connect()
  File "c:\users\shikhar singh\appdata\local\programs\python\python37\lib\site-packages\urllib3\connection.py", line 300, in connect
    conn = self._new_conn()
  File "c:\users\shikhar singh\appdata\local\programs\python\python37\lib\site-packages\urllib3\connection.py", line 169, in _new_conn
    self, "Failed to establish a new connection: %s" % e
urllib3.exceptions.NewConnectionError: <urllib3.connection.VerifiedHTTPSConnection object at 0x0000020D04A79DA0>: Failed to establish a new connection: [Errno 11001] getaddrinfo failed

During handling of the above exception, another exception occurred:

Traceback (most recent call last):
  File "c:\users\shikhar singh\appdata\local\programs\python\python37\lib\site-packages\requests\adapters.py", line 449, in send
    timeout=timeout
  File "c:\users\shikhar singh\appdata\local\programs\python\python37\lib\site-packages\urllib3\connectionpool.py", line 720, in urlopen
    method, url, error=e, _pool=self, _stacktrace=sys.exc_info()[2]
  File "c:\users\shikhar singh\appdata\local\programs\python\python37\lib\site-packages\urllib3\util\retry.py", line 436, in increment
    raise MaxRetryError(_pool, url, error or ResponseError(cause))
urllib3.exceptions.MaxRetryError: HTTPSConnectionPool(host='api.microsofttranslator.com', port=443): Max retries exceeded with url: /v2/Ajax.svc/Translate?text=Hola%20a%20todos,%20esto%20es%20elite!%20No%20existo%20pero%20todav%C3%ADa%20puedo%20escribir%20blog.%20%C2%BFPuedes?&from=es&to=en (Caused by NewConnectionError('<urllib3.connection.VerifiedHTTPSConnection object at 0x0000020D04A79DA0>: Failed to establish a new connection: [Errno 11001] getaddrinfo failed'))

During handling of the above exception, another exception occurred:

Traceback (most recent call last):
  File "c:\users\shikhar singh\appdata\local\programs\python\python37\lib\site-packages\flask\app.py", line 2446, in wsgi_app
    response = self.full_dispatch_request()
  File "c:\users\shikhar singh\appdata\local\programs\python\python37\lib\site-packages\flask\app.py", line 1951, in full_dispatch_request
    rv = self.handle_user_exception(e)
  File "c:\users\shikhar singh\appdata\local\programs\python\python37\lib\site-packages\flask\app.py", line 1820, in handle_user_exception
    reraise(exc_type, exc_value, tb)
  File "c:\users\shikhar singh\appdata\local\programs\python\python37\lib\site-packages\flask\_compat.py", line 39, in reraise
    raise value
  File "c:\users\shikhar singh\appdata\local\programs\python\python37\lib\site-packages\flask\app.py", line 1949, in full_dispatch_request
    rv = self.dispatch_request()
  File "c:\users\shikhar singh\appdata\local\programs\python\python37\lib\site-packages\flask\app.py", line 1935, in dispatch_request
    return self.view_functions[rule.endpoint](**req.view_args)
  File "c:\users\shikhar singh\appdata\local\programs\python\python37\lib\site-packages\flask_login\utils.py", line 272, in decorated_view
    return func(*args, **kwargs)
  File "D:\Previous Laptop\vit materials\Projects\Microblog\app\routes.py", line 206, in translate_text
    request.form['dest_language'])})
  File "D:\Previous Laptop\vit materials\Projects\Microblog\app\translate.py", line 15, in translate
    headers=auth)
  File "c:\users\shikhar singh\appdata\local\programs\python\python37\lib\site-packages\requests\api.py", line 76, in get
    return request('get', url, params=params, **kwargs)
  File "c:\users\shikhar singh\appdata\local\programs\python\python37\lib\site-packages\requests\api.py", line 61, in request
    return session.request(method=method, url=url, **kwargs)
  File "c:\users\shikhar singh\appdata\local\programs\python\python37\lib\site-packages\requests\sessions.py", line 530, in request
    resp = self.send(prep, **send_kwargs)
  File "c:\users\shikhar singh\appdata\local\programs\python\python37\lib\site-packages\requests\sessions.py", line 643, in send
    r = adapter.send(request, **kwargs)
  File "c:\users\shikhar singh\appdata\local\programs\python\python37\lib\site-packages\requests\adapters.py", line 516, in send
    raise ConnectionError(e, request=request)
requests.exceptions.ConnectionError: HTTPSConnectionPool(host='api.microsofttranslator.com', port=443): Max retries exceeded with url: /v2/Ajax.svc/Translate?text=Hola%20a%20todos,%20esto%20es%20elite!%20No%20existo%20pero%20todav%C3%ADa%20puedo%20escribir%20blog.%20%C2%BFPuedes?&from=es&to=en (Caused by NewConnectionError('<urllib3.connection.VerifiedHTTPSConnection object at 0x0000020D04A79DA0>: Failed to establish a new connection: [Errno 11001] getaddrinfo failed'))
2020-04-26 22:14:13,340 INFO: Microblog startup [in D:\Previous Laptop\vit materials\Projects\Microblog\app\__init__.py:52]
2020-04-29 23:05:51,785 INFO: Microblog startup [in D:\Previous Laptop\vit materials\Projects\Microblog\app\__init__.py:52]
2020-04-29 23:07:25,018 INFO: Microblog startup [in D:\Previous Laptop\vit materials\Projects\Microblog\app\__init__.py:52]
2020-05-04 00:32:14,581 INFO: Microblog startup [in D:\Previous Laptop\vit materials\Projects\Microblog\app\__init__.py:52]
2020-05-05 02:53:27,783 INFO: Microblog startup [in D:\Previous Laptop\vit materials\Projects\Microblog\app\__init__.py:74]
2020-05-05 03:02:16,151 INFO: Microblog startup [in D:\Previous Laptop\vit materials\Projects\Microblog\app\__init__.py:74]
